Workbook

Sheet DASHBOARD
A5: 💰 Blended Sales (DoD): | B5: ='Supporting Analysis'!J15 -> 6575 | D5: 💰 Blended Sales (WoW): | E5: ='Supporting Analysis'!J16 -> 44331 | G5: 💰 Blended Sales (MoM): | H5: ='Supporting Analysis'!J17 -> 160840
A7: 📈 Growth % blended (DoD): | B7: ='Supporting Analysis'!J18 -> 0.053179561 | D7: 📈 Growth % blended (WoW): | E7: ='Supporting Analysis'!J19 -> 0.098471145 | G7: 📈 Growth % blended (MoM): | H7: ='Supporting Analysis'!J20 -> -0.3455883
S50: w

Sheet Cleaned Data
A1: Platform | B1: SKU | C1: Date | D1: Sales | E1: Weeknum
A2: Platform A | B2: SKU 1 - a | C2: 45444 | D2: 257 | E2: =WEEKNUM(Append321[[#This Row],[Date]]) -> 22
A3: Platform A | B3: SKU 1 - a | C3: 45445 | D3: 255 | E3: =WEEKNUM(Append321[[#This Row],[Date]]) -> 23
A4: Platform A | B4: SKU 1 - a | C4: 45446 | D4: 254 | E4: =WEEKNUM(Append321[[#This Row],[Date]]) -> 23
A5: Platform A | B5: SKU 1 - a | C5: 45447 | D5: 173 | E5: =WEEKNUM(Append321[[#This Row],[Date]]) -> 23
A6: Platform A | B6: SKU 1 - a | C6: 45448 | D6: 160 | E6: =WEEKNUM(Append321[[#This Row],[Date]]) -> 23
A7: Platform A | B7: SKU 1 - a | C7: 45449 | D7: 173 | E7: =WEEKNUM(Append321[[#This Row],[Date]]) -> 23
A8: Platform A | B8: SKU 1 - a | C8: 45450 | D8: 147 | E8: =WEEKNUM(Append321[[#This Row],[Date]]) -> 23
A9: Platform A | B9: SKU 1 - a | C9: 45451 | D9: 178 | E9: =WEEKNUM(Append321[[#This Row],[Date]]) -> 23
A10: Platform A | B10: SKU 1 - a | C10: 45452 | D10: 107 | E10: =WEEKNUM(Append321[[#This Row],[Date]]) -> 24
A11: Platform A | B11: SKU 1 - a | C11: 45453 | D11: 145 | E11: =WEEKNUM(Append321[[#This Row],[Date]]) -> 24
A12: Platform A | B12: SKU 1 - a | C12: 45454 | D12: 156 | E12: =WEEKNUM(Append321[[#This Row],[Date]]) -> 24
A13: Platform A | B13: SKU 1 - a | C13: 45455 | D13: 145 | E13: =WEEKNUM(Append321[[#This Row],[Date]]) -> 24
... A4158: AMAZON NOW F | B4158: SKU 4 - B | C4158: 45535 | D4158: 28 | E4158: =WEEKNUM(Append321[[#This Row],[Date]]) -> 35

Sheet DUMP
A2: Platform A | B2: 508 | C2: Column1 | D2: Column2 | E2: Column3 | F2: Column4 | G2: Column5 | H2: Column6 | I2: Column7 | J2: Column8 | K2: Column9 | L2: Column10 | M2: Column11 | N2: Column12 | O2: Column13 | P2: Column14 | Q2: Column15 | R2: Column16 | S2: Column17 | T2: Column18 | U2: Column19 | V2: Column20 | W2: Column21 | X2: Column22 | Y2: Column23 | Z2: Column24 | AA2: Column25 | AB2: Column26 | AC2: Column27 | AD2: Column28 | AE2: Column29 | AF2: Column30 | AG2: Column31 | AH2: Column32 | AI2: Column33 | AJ2: Column34 | AK2: Column35 | AL2: Column36 | AM2: Column37 | AN2: Column38 | AO2: Column39 | AP2: Column40 | AQ2: Column41 | AR2: Column42 | AS2: Column43 | AT2: Column44 | AU2: Column45 | AV2: Column46 | AW2: Column47 | AX2: Column48 | AY2: Column49 | AZ2: Column50 | BA2: Column51 | BB2: Column52 | BC2: Column53 | BD2: Column54 | BE2: Column55 | BF2: Column56 | BG2: Column57 | BH2: Column58 | BI2: Column59 | BJ2: Column60 | BK2: Column61 | BL2: Column62 | BM2: Column63 | BN2: Column64 | BO2: Column65 | BP2: Column66 | BQ2: Column67 | BR2: Column68 | BS2: Column69 | BT2: Column70 | BU2: Column71 | BV2: Column72 | BW2: Column73 | BX2: Column74 | BY2: Column75 | BZ2: Column76 | CA2: Column77 | CB2: Column78 | CC2: Column79 | CD2: Column80 | CE2: Column81 | CF2: Column82 | CG2: Column83 | CH2: Column84 | CI2: Column85 | CJ2: Column86 | CK2: Column87 | CL2: Column88 | CM2: Column89 | CN2: Column90 | CO2: Column91
A3: SKU | B3: 01-Jun | C3: 02-Jun | D3: 03-Jun | E3: 04-Jun | F3: 05-Jun | G3: 06-Jun | H3: 07-Jun | I3: 08-Jun | J3: 09-Jun | K3: 10-Jun | L3: 11-Jun | M3: 12-Jun | N3: 13-Jun | O3: 14-Jun | P3: 15-Jun | Q3: 16-Jun | R3: 17-Jun | S3: 18-Jun | T3: 19-Jun | U3: 20-Jun | V3: 21-Jun | W3: 22-Jun | X3: 23-Jun | Y3: 24-Jun | Z3: 25-Jun | AA3: 26-Jun | AB3: 27-Jun | AC3: 28-Jun | AD3: 29-Jun | AE3: 30-Jun | AF3: 01-Jul | AG3: 02-Jul | AH3: 03-Jul | AI3: 04-Jul | AJ3: 05-Jul | AK3: 06-Jul | AL3: 07-Jul | AM3: 08-Jul | AN3: 09-Jul | AO3: 10-Jul | AP3: 11-Jul | AQ3: 12-Jul | AR3: 13-Jul | AS3: 14-Jul | AT3: 15-Jul | AU3: 16-Jul | AV3: 17-Jul | AW3: 18-Jul | AX3: 19-Jul | AY3: 20-Jul | AZ3: 21-Jul | BA3: 22-Jul | BB3: 23-Jul | BC3: 24-Jul | BD3: 25-Jul | BE3: 26-Jul | BF3: 27-Jul | BG3: 28-Jul | BH3: 29-Jul | BI3: 30-Jul | BJ3: 31-Jul | BK3: 01-Aug | BL3: 02-Aug | BM3: 03-Aug | BN3: 04-Aug | BO3: 05-Aug | BP3: 06-Aug | BQ3: 07-Aug | BR3: 08-Aug | BS3: 09-Aug | BT3: 10-Aug | BU3: 11-Aug | BV3: 12-Aug | BW3: 13-Aug | BX3: 14-Aug | BY3: 15-Aug | BZ3: 16-Aug | CA3: 17-Aug | CB3: 18-Aug | CC3: 19-Aug | CD3: 20-Aug | CE3: 21-Aug | CF3: 22-Aug | CG3: 23-Aug | CH3: 24-Aug | CI3: 25-Aug | CJ3: 26-Aug | CK3: 27-Aug | CL3: 28-Aug | CM3: 29-Aug | CN3: 30-Aug | CO3: 31-Aug
A4: SKU 1 - a | B4: 257 | C4: 255 | D4: 254 | E4: 173 | F4: 160 | G4: 173 | H4: 147 | I4: 178 | J4: 107 | K4: 145 | L4: 156 | M4: 145 | N4: 139 | O4: 165 | P4: 191 | Q4: 182 | R4: 151 | S4: 185 | T4: 192 | U4: 172 | V4: 145 | W4: 134 | X4: 130 | Y4: 161 | Z4: 165 | AA4: 168 | AB4: 167 | AC4: 153 | AD4: 147 | AE4: 171 | AF4: 153 | AG4: 169 | AH4: 166 | AI4: 160 | AJ4: 156 | AK4: 165 | AL4: 151 | AM4: 163 | AN4: 158 | AO4: 174 | AP4: 208 | AQ4: 202 | AR4: 201 | AS4: 198 | AT4: 211 | AU4: 188 | AV4: 239 | AW4: 169 | AX4: 213 | AY4: 200 | AZ4: 188 | BA4: 196 | BB4: 220 | BC4: 222 | BD4: 169 | BE4: 177 | BF4: 186 | BG4: 213 | BH4: 208 | BI4: 216 | BJ4: 225 | BK4: 251 | BL4: 244 | BM4: 251 | BN4: 251 | BO4: 270 | BP4: 230 | BQ4: 266 | BR4: 253 | BS4: 198 | BT4: 290 | BU4: 267 | BV4: 296 | BW4: 280 | BX4: 326 | BY4: 318 | BZ4: 264 | CA4: 249 | CB4: 258 | CC4: 236 | CD4: 274 | CE4: 290 | CF4: 275 | CG4: 261 | CH4: 296 | CI4: 240 | CJ4: 285 | CK4: 205 | CL4: 257 | CM4: 218 | CN4: 188 | CO4: 247
A5: SKU 1 - b | B5: 221 | C5: 219 | D5: 252 | E5: 232 | F5: 239 | G5: 208 | H5: 223 | I5: 212 | J5: 218 | K5: 200 | L5: 226 | M5: 242 | N5: 245 | O5: 197 | P5: 227 | Q5: 220 | R5: 224 | S5: 222 | T5: 199 | U5: 214 | V5: 217 | W5: 205 | X5: 204 | Y5: 250 | Z5: 249 | AA5: 232 | AB5: 217 | AC5: 232 | AD5: 220 | AE5: 209 | AF5: 227 | AG5: 240 | AH5: 230 | AI5: 223 | AJ5: 221 | AK5: 220 | AL5: 195 | AM5: 191 | AN5: 226 | AO5: 239 | AP5: 285 | AQ5: 267 | AR5: 281 | AS5: 269 | AT5: 303 | AU5: 303 | AV5: 315 | AW5: 269 | AX5: 231 | AY5: 285 | AZ5: 285 | BA5: 312 | BB5: 308 | BC5: 313 | BD5: 265 | BE5: 299 | BF5: 284 | BG5: 282 | BH5: 298 | BI5: 316 | BJ5: 329 | BK5: 304 | BL5: 294 | BM5: 363 | BN5: 316 | BO5: 368 | BP5: 339 | BQ5: 351 | BR5: 326 | BS5: 278 | BT5: 401 | BU5: 321 | BV5: 318 | BW5: 360 | BX5: 349 | BY5: 304 | BZ5: 289 | CA5: 321 | CB5: 272 | CC5: 316 | CD5: 282 | CE5: 320 | CF5: 298 | CG5: 334 | CH5: 328 | CI5: 282 | CJ5: 286 | CK5: 276 | CL5: 279 | CM5: 278 | CN5: 260 | CO5: 300
A6: SKU 1 - c | B6: 397 | C6: 388 | D6: 401 | E6: 452 | F6: 404 | G6: 451 | H6: 427 | I6: 435 | J6: 362 | K6: 394 | L6: 389 | M6: 435 | N6: 384 | O6: 390 | P6: 482 | Q6: 431 | R6: 361 | S6: 423 | T6: 385 | U6: 365 | V6: 444 | W6: 423 | X6: 365 | Y6: 357 | Z6: 416 | AA6: 380 | AB6: 364 | AC6: 371 | AD6: 349 | AE6: 336 | AF6: 362 | AG6: 395 | AH6: 389 | AI6: 392 | AJ6: 376 | AK6: 443 | AL6: 423 | AM6: 378 | AN6: 388 | AO6: 471 | AP6: 541 | AQ6: 475 | AR6: 536 | AS6: 467 | AT6: 521 | AU6: 493 | AV6: 568 | AW6: 501 | AX6: 572 | AY6: 540 | AZ6: 478 | BA6: 589 | BB6: 485 | BC6: 552 | BD6: 469 | BE6: 531 | BF6: 468 | BG6: 531 | BH6: 543 | BI6: 538 | BJ6: 578 | BK6: 524 | BL6: 565 | BM6: 753 | BN6: 647 | BO6: 640 | BP6: 642 | BQ6: 665 | BR6: 511 | BS6: 498 | BT6: 727 | BU6: 582 | BV6: 586 | BW6: 623 | BX6: 666 | BY6: 655 | BZ6: 551 | CA6: 598 | CB6: 595 | CC6: 584 | CD6: 589 | CE6: 585 | CF6: 571 | CG6: 590 | CH6: 625 | CI6: 544 | CJ6: 491 | CK6: 532 | CL6: 562 | CM6: 495 | CN6: 512 | CO6: 540
A7: SKU 1 - d | BZ7: 1 | CA7: 6 | CB7: 13 | CC7: 31 | CD7: 35 | CE7: 40 | CF7: 53 | CG7: 61 | CH7: 82 | CI7: 80 | CJ7: 72 | CK7: 121 | CL7: 108 | CM7: 152 | CN7: 154 | CO7: 208
A8: SKU 1 - e | BZ8: 1 | CA8: 2 | CB8: 15 | CC8: 40 | CD8: 52 | CE8: 59 | CF8: 33 | CG8: 41 | CH8: 59 | CI8: 56 | CJ8: 59 | CK8: 59 | CL8: 74 | CM8: 112 | CN8: 119 | CO8: 147
A9: SKU 1 - f | B9: 341 | C9: 295 | D9: 277 | E9: 295 | F9: 266 | G9: 360 | H9: 390 | I9: 463 | J9: 343 | K9: 391 | L9: 437 | M9: 514 | N9: 434 | O9: 496 | P9: 430 | Q9: 339 | R9: 283 | S9: 318 | T9: 290 | U9: 277 | V9: 317 | W9: 322 | X9: 274 | Y9: 253 | Z9: 254 | AA9: 279 | AB9: 268 | AC9: 325 | AD9: 280 | AE9: 213 | AF9: 259 | AG9: 277 | AH9: 318 | AI9: 279 | AJ9: 300 | AK9: 309 | AL9: 221 | AM9: 259 | AN9: 218 | AO9: 245 | AP9: 238 | AQ9: 269 | AR9: 271 | AS9: 170 | AT9: 205 | AU9: 200 | AV9: 239 | AW9: 205 | AX9: 289 | AY9: 289 | AZ9: 205 | BA9: 213 | BB9: 190 | BC9: 236 | BD9: 225 | BE9: 259 | BF9: 277 | BG9: 202 | BH9: 185 | BI9: 164 | BJ9: 187 | BK9: 209 | BL9: 262 | BM9: 249 | BN9: 199 | BO9: 206 | BP9: 206 | BQ9: 231 | BR9: 231 | BS9: 213 | BT9: 250 | BU9: 207 | BV9: 207 | BW9: 200 | BX9: 181 | BY9: 249 | BZ9: 228 | CA9: 273 | CB9: 206 | CC9: 207 | CD9: 227 | CE9: 231 | CF9: 194 | CG9: 247 | CH9: 295 | CI9: 192 | CJ9: 203 | CK9: 223 | CL9: 230 | CM9: 202 | CN9: 239 | CO9: 278
A10: SKU 1 - h | B10: 347 | C10: 261 | D10: 250 | E10: 229 | F10: 243 | G10: 340 | H10: 339 | I10: 409 | J10: 315 | K10: 294 | L10: 340 | M10: 385 | N10: 349 | O10: 436 | P10: 316 | Q10: 266 | R10: 217 | S10: 257 | T10: 241 | U10: 243 | V10: 274 | W10: 308 | X10: 226 | Y10: 233 | Z10: 239 | AA10: 257 | AB10: 241 | AC10: 322 | AD10: 295 | AE10: 235 | AF10: 244 | AG10: 272 | AH10: 247 | AI10: 230 | AJ10: 282 | AK10: 261 | AL10: 188 | AM10: 220 | AN10: 189 | AO10: 180 | AP10: 234 | AQ10: 260 | AR10: 265 | AS10: 189 | AT10: 183 | AU10: 176 | AV10: 179 | AW10: 193 | AX10: 250 | AY10: 227 | AZ10: 175 | BA10: 209 | BB10: 142 | BC10: 182 | BD10: 198 | BE10: 224 | BF10: 242 | BG10: 182 | BH10: 133 | BI10: 156 | BJ10: 186 | BK10: 173 | BL10: 210 | BM10: 202 | BN10: 147 | BO10: 176 | BP10: 183 | BQ10: 207 | BR10: 204 | BS10: 194 | BT10: 227 | BU10: 151 | BV10: 223 | BW10: 174 | BX10: 168 | BY10: 200 | BZ10: 182 | CA10: 219 | CB10: 155 | CC10: 169 | CD10: 198 | CE10: 202 | CF10: 199 | CG10: 204 | CH10: 214 | CI10: 171 | CJ10: 164 | CK10: 212 | CL10: 238 | CM10: 197 | CN10: 278 | CO10: 291
A11: SKU 2 - a | B11: 93 | C11: 73 | D11: 73 | E11: 64 | F11: 61 | G11: 71 | H11: 70 | I11: 82 | J11: 66 | K11: 65 | L11: 73 | M11: 51 | N11: 73 | O11: 81 | P11: 80 | Q11: 71 | R11: 78 | S11: 77 | T11: 49 | U11: 69 | V11: 77 | W11: 94 | X11: 60 | Y11: 80 | Z11: 55 | AA11: 71 | AB11: 81 | AC11: 96 | AD11: 91 | AE11: 97 | AF11: 89 | AG11: 73 | AH11: 97 | AI11: 92 | AJ11: 87 | AK11: 101 | AL11: 79 | AM11: 80 | AN11: 81 | AO11: 86 | AP11: 94 | AQ11: 99 | AR11: 121 | AS11: 108 | AT11: 102 | AU11: 96 | AV11: 121 | AW11: 104 | AX11: 109 | AY11: 119 | AZ11: 96 | BA11: 96 | BB11: 96 | BC11: 96 | BD11: 95 | BE11: 112 | BF11: 110 | BG11: 107 | BH11: 111 | BI11: 90 | BJ11: 110 | BK11: 135 | BL11: 148 | BM11: 166 | BN11: 126 | BO11: 162 | BP11: 145 | BQ11: 154 | BR11: 137 | BS11: 140 | BT11: 157 | BU11: 136 | BV11: 127 | BW11: 130 | BX11: 132 | BY11: 155 | BZ11: 152 | CA11: 176 | CB11: 160 | CC11: 164 | CD11: 154 | CE11: 144 | CF11: 147 | CG11: 145 | CH11: 175 | CI11: 120 | CJ11: 141 | CK11: 158 | CL11: 134 | CM11: 144 | CN11: 183 | CO11: 156
A12: SKU 2 - B | B12: 283 | C12: 206 | D12: 246 | E12: 260 | F12: 235 | G12: 219 | H12: 225 | I12: 248 | J12: 197 | K12: 224 | L12: 205 | M12: 206 | N12: 196 | O12: 242 | P12: 271 | Q12: 197 | R12: 232 | S12: 230 | T12: 233 | U12: 204 | V12: 212 | W12: 286 | X12: 201 | Y12: 208 | Z12: 248 | AA12: 211 | AB12: 227 | AC12: 256 | AD12: 283 | AE12: 259 | AF12: 256 | AG12: 232 | AH12: 246 | AI12: 195 | AJ12: 222 | AK12: 248 | AL12: 188 | AM12: 176 | AN12: 179 | AO12: 207 | AP12: 196 | AQ12: 228 | AR12: 255 | AS12: 200 | AT12: 207 | AU12: 204 | AV12: 271 | AW12: 212 | AX12: 242 | AY12: 265 | AZ12: 215 | BA12: 194 | BB12: 227 | BC12: 214 | BD12: 202 | BE12: 225 | BF12: 281 | BG12: 223 | BH12: 227 | BI12: 192 | BJ12: 235 | BK12: 226 | BL12: 261 | BM12: 330 | BN12: 256 | BO12: 238 | BP12: 196 | BQ12: 240 | BR12: 205 | BS12: 194 | BT12: 278 | BU12: 190 | BV12: 180 | BW12: 164 | BX12: 199 | BY12: 206 | BZ12: 218 | CA12: 199 | CB12: 183 | CC12: 157 | CD12: 180 | CE12: 190 | CF12: 180 | CG12: 192 | CH12: 213 | CI12: 148 | CJ12: 171 | CK12: 175 | CL12: 174 | CM12: 171 | CN12: 181 | CO12: 230
A13: SKU 2 - C | B13: 92 | C13: 67 | D13: 73 | E13: 66 | F13: 64 | G13: 65 | H13: 63 | I13: 71 | J13: 55 | K13: 61 | L13: 62 | M13: 45 | N13: 57 | O13: 71 | P13: 79 | Q13: 45 | R13: 58 | S13: 65 | T13: 70 | U13: 62 | V13: 71 | W13: 72 | X13: 53 | Y13: 64 | Z13: 69 | AA13: 74 | AB13: 67 | AC13: 85 | AD13: 79 | AE13: 83 | AF13: 98 | AG13: 108 | AH13: 66 | AI13: 63 | AJ13: 78 | AK13: 83 | AL13: 69 | AM13: 65 | AN13: 92 | AO13: 110 | AP13: 83 | AQ13: 120 | AR13: 126 | AS13: 98 | AT13: 86 | AU13: 98 | AV13: 102 | AW13: 112 | AX13: 77 | AY13: 105 | AZ13: 110 | BA13: 86 | BB13: 96 | BC13: 99 | BD13: 86 | BE13: 97 | BF13: 109 | BG13: 95 | BH13: 83 | BI13: 109 | BJ13: 95 | BK13: 107 | BL13: 138 | BM13: 157 | BN13: 117 | BO13: 118 | BP13: 136 | BQ13: 140 | BR13: 141 | BS13: 122 | BT13: 137 | BU13: 106 | BV13: 137 | BW13: 121 | BX13: 129 | BY13: 178 | BZ13: 149 | CA13: 144 | CB13: 125 | CC13: 106 | CD13: 144 | CE13: 136 | CF13: 106 | CG13: 126 | CH13: 167 | CI13: 134 | CJ13: 148 | CK13: 126 | CL13: 130 | CM13: 141 | CN13: 155 | CO13: 140
A14: SKU 2 - D | B14: 312 | C14: 222 | D14: 267 | E14: 225 | F14: 258 | G14: 239 | H14: 288 | I14: 254 | J14: 233 | K14: 220 | L14: 223 | M14: 209 | N14: 239 | O14: 276 | P14: 313 | Q14: 235 | R14: 240 | S14: 223 | T14: 248 | U14: 232 | V14: 274 | W14: 306 | X14: 219 | Y14: 235 | Z14: 237 | AA14: 251 | AB14: 248 | AC14: 270 | AD14: 309 | AE14: 286 | AF14: 251 | AG14: 245 | AH14: 237 | AI14: 219 | AJ14: 255 | AK14: 275 | AL14: 220 | AM14: 214 | AN14: 207 | AO14: 222 | AP14: 214 | AQ14: 226 | AR14: 276 | AS14: 214 | AT14: 190 | AU14: 193 | AV14: 274 | AW14: 223 | AX14: 244 | AY14: 247 | AZ14: 229 | BA14: 239 | BB14: 213 | BC14: 245 | BD14: 210 | BE14: 254 | BF14: 234 | BG14: 228 | BH14: 246 | BI14: 219 | BJ14: 216 | BK14: 228 | BL14: 255 | BM14: 340 | BN14: 247 | BO14: 249 | BP14: 237 | BQ14: 231 | BR14: 249 | BS14: 191 | BT14: 292 | BU14: 213 | BV14: 237 | BW14: 163 | BX14: 187 | BY14: 191 | BZ14: 202 | CA14: 192 | CB14: 186 | CC14: 276 | CD14: 235 | CE14: 277 | CF14: 242 | CG14: 312 | CH14: 294 | CI14: 243 | CJ14: 210 | CK14: 222 | CL14: 186 | CM14: 222 | CN14: 229 | CO14: 325
A15: SKU 3 - A | BY15: 1 | BZ15: 3 | CA15: 7 | CB15: 19 | CC15: 28 | CD15: 42 | CE15: 49 | CF15: 42 | CG15: 30 | CH15: 46 | CI15: 39 | CJ15: 41 | CK15: 44 | CL15: 51 | CM15: 48 | CN15: 54 | CO15: 40
A16: SKU - 3 B | B16: 148 | C16: 135 | D16: 144 | E16: 146 | F16: 172 | G16: 145 | H16: 161 | I16: 142 | J16: 151 | K16: 118 | L16: 163 | M16: 161 | N16: 127 | O16: 150 | P16: 139 | Q16: 143 | R16: 131 | S16: 150 | T16: 157 | U16: 150 | V16: 128 | W16: 137 | X16: 141 | Y16: 153 | Z16: 130 | AA16: 140 | AB16: 139 | AC16: 129 | AD16: 155 | AE16: 128 | AF16: 145 | AG16: 177 | AH16: 179 | AI16: 171 | AJ16: 166 | AK16: 148 | AL16: 142 | AM16: 134 | AN16: 139 | AO16: 209 | AP16: 147 | AQ16: 176 | AR16: 166 | AS16: 190 | AT16: 189 | AU16: 164 | AV16: 219 | AW16: 158 | AX16: 180 | AY16: 166 | AZ16: 147 | BA16: 162 | BB16: 157 | BC16: 187 | BD16: 154 | BE16: 178 | BF16: 191 | BG16: 152 | BH16: 183 | BI16: 188 | BJ16: 195 | BK16: 165 | BL16: 230 | BM16: 186 | BN16: 190 | BO16: 176 | BP16: 190 | BQ16: 172 | BR16: 143 | BS16: 128 | BT16: 194 | BU16: 199 | BV16: 181 | BW16: 207 | BX16: 180 | BY16: 222 | BZ16: 176 | CA16: 216 | CB16: 220 | CC16: 207 | CD16: 199 | CE16: 205 | CF16: 195 | CG16: 201 | CH16: 190 | CI16: 184 | CJ16: 202 | CK16: 204 | CL16: 235 | CM16: 215 | CN16: 193 | CO16: 234
A17: SKU - 3 C | CD17: 1 | CE17: 6 | CF17: 6 | CG17: 4 | CH17: 11 | CI17: 8 | CJ17: 6 | CK17: 6 | CL17: 5 | CM17: 5 | CN17: 7 | CO17: 6
A18: SKU 4 - A
A19: SKU 4 - B
A21: Platform B | B21: Column1 | C21: Column2 | D21: Column3 | E21: Column4 | F21: Column5 | G21: Column6 | H21: Column7 | I21: Column8 | J21: Column9 | K21: Column10 | L21: Column11 | M21: Column12 | N21: Column13 | O21: Column14 | P21: Column15 | Q21: Column16 | R21: Column17 | S21: Column18 | T21: Column19 | U21: Column20 | V21: Column21 | W21: Column22 | X21: Column23 | Y21: Column24 | Z21: Column25 | AA21: Column26 | AB21: Column27 | AC21: Column28 | AD21: Column29 | AE21: Column30 | AF21: Column31 | AG21: Column32 | AH21: Column33 | AI21: Column34 | AJ21: Column35 | AK21: Column36 | AL21: Column37 | AM21: Column38 | AN21: Column39 | AO21: Column40 | AP21: Column41 | AQ21: Column42 | AR21: Column43 | AS21: Column44 | AT21: Column45 | AU21: Column46 | AV21: Column47 | AW21: Column48 | AX21: Column49 | AY21: Column50 | AZ21: Column51 | BA21: Column52 | BB21: Column53 | BC21: Column54 | BD21: Column55 | BE21: Column56 | BF21: Column57 | BG21: Column58 | BH21: Column59 | BI21: Column60 | BJ21: Column61 | BK21: Column62 | BL21: Column63 | BM21: Column64 | BN21: Column65 | BO21: Column66 | BP21: Column67 | BQ21: Column68 | BR21: Column69 | BS21: Column70 | BT21: Column71 | BU21: Column72 | BV21: Column73 | BW21: Column74 | BX21: Column75 | BY21: Column76 | BZ21: Column77 | CA21: Column78 | CB21: Column79 | CC21: Column80 | CD21: Column81 | CE21: Column82 | CF21: Column83 | CG21: Column84 | CH21: Column85 | CI21: Column86 | CJ21: Column87 | CK21: Column88 | CL21: Column89 | CM21: Column90 | CN21: Column91 | CO21: Column92
A22: SKU | B22: 01-Jun | C22: 02-Jun | D22: 03-Jun | E22: 04-Jun | F22: 05-Jun | G22: 06-Jun | H22: 07-Jun | I22: 08-Jun | J22: 09-Jun | K22: 10-Jun | L22: 11-Jun | M22: 12-Jun | N22: 13-Jun | O22: 14-Jun | P22: 15-Jun | Q22: 16-Jun | R22: 17-Jun | S22: 18-Jun | T22: 19-Jun | U22: 20-Jun | V22: 21-Jun | W22: 22-Jun | X22: 23-Jun | Y22: 24-Jun | Z22: 25-Jun | AA22: 26-Jun | AB22: 27-Jun | AC22: 28-Jun | AD22: 29-Jun | AE22: 30-Jun | AF22: 01-Jul | AG22: 02-Jul | AH22: 03-Jul | AI22: 04-Jul | AJ22: 05-Jul | AK22: 06-Jul | AL22: 07-Jul | AM22: 08-Jul | AN22: 09-Jul | AO22: 10-Jul | AP22: 11-Jul | AQ22: 12-Jul | AR22: 13-Jul | AS22: 14-Jul | AT22: 15-Jul | AU22: 16-Jul | AV22: 17-Jul | AW22: 18-Jul | AX22: 19-Jul | AY22: 20-Jul | AZ22: 21-Jul | BA22: 22-Jul | BB22: 23-Jul | BC22: 24-Jul | BD22: 25-Jul | BE22: 26-Jul | BF22: 27-Jul | BG22: 28-Jul | BH22: 29-Jul | BI22: 30-Jul | BJ22: 31-Jul | BK22: 01-Aug | BL22: 02-Aug | BM22: 03-Aug | BN22: 04-Aug | BO22: 05-Aug | BP22: 06-Aug | BQ22: 07-Aug | BR22: 08-Aug | BS22: 09-Aug | BT22: 10-Aug | BU22: 11-Aug | BV22: 12-Aug | BW22: 13-Aug | BX22: 14-Aug | BY22: 15-Aug | BZ22: 16-Aug | CA22: 17-Aug | CB22: 18-Aug | CC22: 19-Aug | CD22: 20-Aug | CE22: 21-Aug | CF22: 22-Aug | CG22: 23-Aug | CH22: 24-Aug | CI22: 25-Aug | CJ22: 26-Aug | CK22: 27-Aug | CL22: 28-Aug | CM22: 29-Aug | CN22: 30-Aug | CO22: 31-Aug
A23: SKU 1 - a | B23: 11 | C23: 13 | D23: 6 | E23: 7 | F23: 6 | G23: 5 | H23: 2 | I23: 4 | K23: 2 | L23: 6 | M23: 5 | N23: 3 | O23: 6 | P23: 4 | Q23: 2 | R23: 4 | S23: 3 | T23: 1 | V23: 3 | W23: 18 | X23: 10 | Y23: 18 | Z23: 15 | AA23: 8 | AB23: 11 | AC23: 15 | AD23: 28 | AE23: 25 | AF23: 32 | AG23: 43 | AH23: 46 | AI23: 61 | AJ23: 36 | AK23: 65 | AL23: 33 | AM23: 59 | AN23: 54 | AO23: 64 | AP23: 46 | AQ23: 65 | AR23: 76 | AS23: 67 | AT23: 58 | AU23: 77 | AV23: 64 | AW23: 82 | AX23: 75 | AY23: 102 | AZ23: 81 | BA23: 75 | BB23: 87 | BC23: 82 | BD23: 70 | BE23: 119 | BF23: 89 | BG23: 84 | BH23: 91 | BI23: 115 | BJ23: 96 | BK23: 100 | BL23: 91 | BM23: 80 | BN23: 89 | BO23: 117 | BP23: 85 | BQ23: 85 | BR23: 77 | BS23: 71 | BT23: 81 | BU23: 90 | BV23: 86 | BW23: 68 | BX23: 74 | BY23: 81 | BZ23: 112 | CA23: 91 | CB23: 88 | CC23: 101 | CD23: 83 | CE23: 91 | CF23: 101 | CG23: 72 | CH23: 80 | CI23: 87 | CJ23: 102 | CK23: 88 | CL23: 97 | CM23: 102 | CN23: 108 | CO23: 113
A24: SKU 1 - b | B24: 127 | C24: 103 | D24: 118 | E24: 117 | F24: 127 | G24: 106 | H24: 122 | I24: 96 | J24: 122 | K24: 97 | L24: 111 | M24: 119 | N24: 130 | O24: 184 | P24: 169 | Q24: 170 | R24: 154 | S24: 147 | T24: 114 | U24: 110 | V24: 117 | W24: 110 | X24: 85 | Y24: 103 | Z24: 99 | AA24: 116 | AB24: 107 | AC24: 100 | AD24: 112 | AE24: 145 | AF24: 141 | AG24: 206 | AH24: 176 | AI24: 175 | AJ24: 170 | AK24: 193 | AL24: 152 | AM24: 172 | AN24: 159 | AO24: 102 | AP24: 132 | AQ24: 132 | AR24: 131 | AS24: 123 | AT24: 151 | AU24: 117 | AV24: 138 | AW24: 121 | AX24: 447 | AY24: 518 | AZ24: 58 | BA24: 103 | BB24: 93 | BC24: 100 | BD24: 106 | BE24: 689 | BF24: 204 | BG24: 69 | BH24: 84 | BI24: 129 | BJ24: 117 | BK24: 97 | BL24: 146 | BM24: 130 | BN24: 133 | BO24: 139 | BP24: 126 | BQ24: 126 | BR24: 125 | BS24: 127 | BT24: 164 | BU24: 123 | BV24: 122 | BW24: 142 | BX24: 192 | BY24: 248 | BZ24: 182 | CA24: 172 | CB24: 140 | CC24: 170 | CD24: 158 | CE24: 125 | CF24: 144 | CG24: 131 | CH24: 121 | CI24: 135 | CJ24: 161 | CK24: 153 | CL24: 162 | CM24: 173 | CN24: 148 | CO24: 117
A25: SKU 1 - c | B25: 124 | C25: 114 | D25: 132 | E25: 134 | F25: 156 | G25: 126 | H25: 139 | I25: 132 | J25: 121 | K25: 93 | L25: 118 | M25: 119 | N25: 132 | O25: 159 | P25: 152 | Q25: 139 | R25: 134 | S25: 175 | T25: 138 | U25: 111 | V25: 133 | W25: 147 | X25: 126 | Y25: 132 | Z25: 111 | AA25: 131 | AB25: 147 | AC25: 158 | AD25: 188 | AE25: 167 | AF25: 222 | AG25: 310 | AH25: 238 | AI25: 212 | AJ25: 197 | AK25: 287 | AL25: 190 | AM25: 203 | AN25: 214 | AO25: 182 | AP25: 198 | AQ25: 186 | AR25: 204 | AS25: 133 | AT25: 197 | AU25: 162 | AV25: 153 | AW25: 130 | AX25: 133 | AY25: 178 | AZ25: 149 | BA25: 158 | BB25: 455 | BC25: 393 | BD25: 136 | BE25: 201 | BF25: 224 | BG25: 192 | BH25: 197 | BI25: 241 | BJ25: 198 | BK25: 195 | BL25: 238 | BM25: 221 | BN25: 210 | BO25: 215 | BP25: 192 | BQ25: 209 | BR25: 175 | BS25: 161 | BT25: 184 | BU25: 169 | BV25: 183 | BW25: 199 | BX25: 301 | BY25: 349 | BZ25: 194 | CA25: 253 | CB25: 207 | CC25: 235 | CD25: 261 | CE25: 219 | CF25: 231 | CG25: 222 | CH25: 218 | CI25: 220 | CJ25: 231 | CK25: 235 | CL25: 209 | CM25: 259 | CN25: 244 | CO25: 256
A26: SKU 1 - d
A27: SKU 1 - e
A28: SKU 1 - f | B28: 17 | C28: 3 | D28: 14 | E28: 12 | F28: 13 | G28: 6 | H28: 12 | I28: 15 | J28: 17 | K28: 9 | L28: 13 | M28: 20 | N28: 13 | O28: 26 | P28: 23 | Q28: 16 | R28: 10 | S28: 11 | T28: 4 | U28: 11 | V28: 14 | W28: 10 | X28: 8 | Y28: 12 | Z28: 8 | AA28: 14 | AB28: 8 | AC28: 10 | AD28: 10 | AE28: 6 | AF28: 11 | AG28: 14 | AH28: 17 | AI28: 23 | AJ28: 27 | AK28: 27 | AL28: 19 | AM28: 26 | AN28: 22 | AO28: 18 | AP28: 22 | AQ28: 25 | AR28: 23 | AS28: 24 | AT28: 23 | AU28: 18 | AV28: 23 | AW28: 21 | AX28: 29 | AY28: 40 | AZ28: 20 | BA28: 26 | BB28: 25 | BC28: 15 | BD28: 22 | BE28: 30 | BF28: 38 | BG28: 22 | BH28: 31 | BI28: 40 | BJ28: 25 | BK28: 33 | BL28: 36 | BM28: 47 | BN28: 28 | BO28: 38 | BP28: 26 | BQ28: 35 | BR28: 35 | BS28: 27 | BT28: 38 | BU28: 35 | BV28: 29 | BW28: 26 | BX28: 27 | BY28: 30 | BZ28: 32 | CA28: 24 | CB28: 21 | CC28: 31 | CD28: 31 | CE28: 28 | CF28: 34 | CG28: 35 | CH28: 40 | CI28: 24 | CJ28: 33 | CK28: 31 | CL28: 29 | CM28: 29 | CN28: 36 | CO28: 31
A29: SKU 1 - h | B29: 9 | C29: 12 | D29: 9 | E29: 5 | F29: 9 | G29: 8 | H29: 7 | I29: 8 | J29: 12 | K29: 6 | L29: 9 | M29: 9 | N29: 7 | O29: 10 | P29: 10 | Q29: 6 | R29: 6 | S29: 3 | T29: 9 | U29: 5 | V29: 7 | W29: 5 | X29: 3 | Y29: 7 | Z29: 6 | AA29: 5 | AB29: 5 | AC29: 6 | AD29: 10 | AE29: 6 | AF29: 13 | AG29: 14 | AH29: 10 | AI29: 15 | AJ29: 15 | AK29: 15 | AL29: 15 | AM29: 28 | AN29: 8 | AO29: 18 | AP29: 19 | AQ29: 25 | AR29: 25 | AS29: 20 | AT29: 25 | AU29: 17 | AV29: 14 | AW29: 21 | AX29: 23 | AY29: 35 | AZ29: 17 | BA29: 22 | BB29: 25 | BC29: 23 | BD29: 28 | BE29: 30 | BF29: 45 | BG29: 17 | BH29: 24 | BI29: 26 | BJ29: 41 | BK29: 52 | BL29: 38 | BM29: 41 | BN29: 37 | BO29: 32 | BP29: 30 | BQ29: 50 | BR29: 42 | BS29: 35 | BT29: 42 | BU29: 22 | BV29: 26 | BW29: 23 | BX29: 30 | BY29: 32 | BZ29: 35 | CA29: 23 | CB29: 20 | CC29: 15 | CD29: 27 | CE29: 31 | CF29: 26 | CG29: 31 | CH29: 46 | CI29: 16 | CJ29: 32 | CK29: 36 | CL29: 41 | CM29: 25 | CN29: 28 | CO29: 30
A30: SKU 2 - a | B30: 54 | C30: 34 | D30: 23 | E30: 40 | F30: 46 | G30: 28 | H30: 41 | I30: 47 | J30: 26 | K30: 34 | L30: 43 | M30: 39 | N30: 38 | O30: 48 | P30: 46 | Q30: 40 | R30: 36 | S30: 35 | T30: 47 | U30: 50 | V30: 46 | W30: 47 | X30: 43 | Y30: 48 | Z30: 37 | AA30: 40 | AB30: 26 | AC30: 48 | AD30: 55 | AE30: 47 | AF30: 68 | AG30: 95 | AH30: 61 | AI30: 86 | AJ30: 61 | AK30: 100 | AL30: 69 | AM30: 65 | AN30: 67 | AO30: 46 | AP30: 62 | AQ30: 66 | AR30: 50 | AS30: 58 | AT30: 46 | AU30: 50 | AV30: 62 | AW30: 60 | AX30: 50 | AY30: 60 | AZ30: 50 | BA30: 32 | BB30: 57 | BC30: 74 | BD30: 74 | BE30: 81 | BF30: 78 | BG30: 74 | BH30: 66 | BI30: 58 | BJ30: 58 | BK30: 74 | BL30: 77 | BM30: 87 | BN30: 70 | BO30: 76 | BP30: 45 | BQ30: 61 | BR30: 51 | BS30: 41 | BT30: 77 | BU30: 53 | BV30: 50 | BW30: 67 | BX30: 76 | BY30: 91 | BZ30: 63 | CA30: 81 | CB30: 63 | CC30: 62 | CD30: 50 | CE30: 55 | CF30: 53 | CG30: 59 | CH30: 65 | CI30: 58 | CJ30: 57 | CK30: 49 | CL30: 54 | CM30: 66 | CN30: 71 | CO30: 78
A31: SKU 2 - B
A32: SKU 2 - C | B32: 28 | C32: 13 | D32: 18 | E32: 25 | F32: 22 | G32: 24 | H32: 22 | I32: 32 | J32: 20 | K32: 22 | L32: 23 | M32: 25 | N32: 25 | O32: 29 | P32: 35 | Q32: 25 | R32: 28 | S32: 28 | T32: 27 | U32: 22 | V32: 34 | W32: 33 | X32: 30 | Y32: 26 | Z32: 31 | AA32: 25 | AB32: 22 | AC32: 34 | AD32: 30 | AE32: 31 | AF32: 40 | AG32: 40 | AH32: 54 | AI32: 62 | AJ32: 52 | AK32: 73 | AL32: 38 | AM32: 36 | AN32: 47 | AO32: 31 | AP32: 46 | AQ32: 45 | AR32: 55 | AS32: 35 | AT32: 47 | AU32: 45 | AV32: 35 | AW32: 35 | AX32: 50 | AY32: 61 | AZ32: 42 | BA32: 37 | BB32: 50 | BC32: 41 | BD32: 44 | BE32: 60 | BF32: 55 | BG32: 52 | BH32: 39 | BI32: 49 | BJ32: 48 | BK32: 67 | BL32: 54 | BM32: 73 | BN32: 55 | BO32: 44 | BP32: 43 | BQ32: 43 | BR32: 54 | BS32: 36 | BT32: 64 | BU32: 40 | BV32: 38 | BW32: 56 | BX32: 47 | BY32: 61 | BZ32: 68 | CA32: 46 | CB32: 44 | CC32: 37 | CD32: 52 | CE32: 39 | CF32: 39 | CG32: 45 | CH32: 53 | CI32: 30 | CJ32: 45 | CK32: 27 | CL32: 31 | CM32: 53 | CN32: 68 | CO32: 58
A33: SKU 2 - D
A34: SKU 3 - A | B34: 1 | I34: 1 | Q34: 1 | V34: 1 | AC34: 2 | AD34: 1 | AE34: 1 | AG34: 5 | AH34: 5 | AI34: 8 | AJ34: 7 | AK34: 11 | AL34: 5 | AM34: 6 | AN34: 6 | AO34: 6 | AP34: 7 | AQ34: 14 | AR34: 11 | AS34: 7 | AT34: 20 | AU34: 18 | AV34: 9 | AW34: 21 | AX34: 18 | AY34: 20 | AZ34: 22 | BA34: 25 | BB34: 24 | BC34: 32 | BD34: 19 | BE34: 30 | BF34: 24 | BG34: 23 | BH34: 25 | BI34: 28 | BJ34: 33 | BK34: 48 | BL34: 44 | BM34: 41 | BN34: 36 | BO34: 41 | BP34: 29 | BQ34: 38 | BR34: 28 | BS34: 24 | BT34: 29 | BU34: 32 | BV34: 40 | BW34: 29 | BX34: 36 | BY34: 44 | BZ34: 35 | CA34: 44 | CB34: 39 | CC34: 35 | CD34: 43 | CE34: 49 | CF34: 45 | CG34: 33 | CH34: 51 | CI34: 31 | CJ34: 36 | CK34: 31 | CL34: 45 | CM34: 41 | CN34: 47 | CO34: 45
A35: SKU - 3 B
A36: SKU - 3 C | B36: 28 | C36: 35 | D36: 23 | E36: 37 | F36: 29 | G36: 32 | H36: 27 | I36: 13 | J36: 15 | K36: 19 | L36: 21 | M36: 19 | N36: 21 | O36: 27 | P36: 22 | Q36: 22 | R36: 20 | S36: 18 | T36: 11 | U36: 7 | V36: 8 | W36: 13 | X36: 5 | Y36: 3 | Z36: 10 | AA36: 8 | AB36: 4 | AC36: 2 | AD36: 9 | AE36: 5 | AZ36: 1 | BA36: 3 | BB36: 4 | BC36: 7 | BD36: 7 | BE36: 16 | BF36: 24 | BG36: 14 | BH36: 22 | BI36: 24 | BJ36: 18 | BK36: 14 | BL36: 12 | BM36: 9 | BN36: 10 | BO36: 16 | BP36: 20 | BQ36: 11 | BR36: 10 | BS36: 14 | BT36: 17 | BU36: 18 | BV36: 39 | BW36: 23 | BX36: 20 | BY36: 23 | BZ36: 29 | CA36: 20 | CB36: 25 | CC36: 30 | CD36: 19 | CE36: 29 | CF36: 19 | CG36: 27 | CH36: 24 | CI36: 26 | CJ36: 20 | CK36: 31 | CL36: 27 | CM36: 25 | CN36: 24 | CO36: 39
A37: SKU 4 - A | BL37: 2 | BM37: 2 | BN37: 1 | BO37: 4 | BP37: 3 | BQ37: 6 | BR37: 4 | BS37: 4 | BT37: 2 | BU37: 4 | BW37: 4 | BX37: 6 | BY37: 7 | BZ37: 1 | CA37: 6 | CB37: 3 | CC37: 1 | CD37: 5 | CE37: 4 | CF37: 1 | CG37: 4 | CH37: 3 | CI37: 1 | CJ37: 4 | CK37: 3 | CL37: 1 | CM37: 6 | CN37: 5 | CO37: 2
A38: SKU 4 - B
A40: Platform C | B40: Column1 | C40: Column2 | D40: Column3 | E40: Column4 | F40: Column5 | G40: Column6 | H40: Column7 | I40: Column8 | J40: Column9 | K40: Column10 | L40: Column11 | M40: Column12 | N40: Column13 | O40: Column14 | P40: Column15 | Q40: Column16 | R40: Column17 | S40: Column18 | T40: Column19 | U40: Column20 | V40: Column21 | W40: Column22 | X40: Column23 | Y40: Column24 | Z40: Column25 | AA40: Column26 | AB40: Column27 | AC40: Column28 | AD40: Column29 | AE40: Column30 | AF40: Column31 | AG40: Column32 | AH40: Column33 | AI40: Column34 | AJ40: Column35 | AK40: Column36 | AL40: Column37 | AM40: Column38 | AN40: Column39 | AO40: Column40 | AP40: Column41 | AQ40: Column42 | AR40: Column43 | AS40: Column44 | AT40: Column45 | AU40: Column46 | AV40: Column47 | AW40: Column48 | AX40: Column49 | AY40: Column50 | AZ40: Column51 | BA40: Column52 | BB40: Column53 | BC40: Column54 | BD40: Column55 | BE40: Column56 | BF40: Column57 | BG40: Column58 | BH40: Column59 | BI40: Column60 | BJ40: Column61 | BK40: Column62 | BL40: Column63 | BM40: Column64 | BN40: Column65 | BO40: Column66 | BP40: Column67 | BQ40: Column68 | BR40: Column69 | BS40: Column70 | BT40: Column71 | BU40: Column72 | BV40: Column73 | BW40: Column74 | BX40: Column75 | BY40: Column76 | BZ40: Column77 | CA40: Column78 | CB40: Column79 | CC40: Column80 | CD40: Column81 | CE40: Column82 | CF40: Column83 | CG40: Column84 | CH40: Column85 | CI40: Column86 | CJ40: Column87 | CK40: Column88 | CL40: Column89 | CM40: Column90 | CN40: Column91 | CO40: Column92
A41: SKU | B41: 01-Jun | C41: 02-Jun | D41: 03-Jun | E41: 04-Jun | F41: 05-Jun | G41: 06-Jun | H41: 07-Jun | I41: 08-Jun | J41: 09-Jun | K41: 10-Jun | L41: 11-Jun | M41: 12-Jun | N41: 13-Jun | O41: 14-Jun | P41: 15-Jun | Q41: 16-Jun | R41: 17-Jun | S41: 18-Jun | T41: 19-Jun | U41: 20-Jun | V41: 21-Jun | W41: 22-Jun | X41: 23-Jun | Y41: 24-Jun | Z41: 25-Jun | AA41: 26-Jun | AB41: 27-Jun | AC41: 28-Jun | AD41: 29-Jun | AE41: 30-Jun | AF41: 01-Jul | AG41: 02-Jul | AH41: 03-Jul | AI41: 04-Jul | AJ41: 05-Jul | AK41: 06-Jul | AL41: 07-Jul | AM41: 08-Jul | AN41: 09-Jul | AO41: 10-Jul | AP41: 11-Jul | AQ41: 12-Jul | AR41: 13-Jul | AS41: 14-Jul | AT41: 15-Jul | AU41: 16-Jul | AV41: 17-Jul | AW41: 18-Jul | AX41: 19-Jul | AY41: 20-Jul | AZ41: 21-Jul | BA41: 22-Jul | BB41: 23-Jul | BC41: 24-Jul | BD41: 25-Jul | BE41: 26-Jul | BF41: 27-Jul | BG41: 28-Jul | BH41: 29-Jul | BI41: 30-Jul | BJ41: 31-Jul | BK41: 01-Aug | BL41: 02-Aug | BM41: 03-Aug | BN41: 04-Aug | BO41: 05-Aug | BP41: 06-Aug | BQ41: 07-Aug | BR41: 08-Aug | BS41: 09-Aug | BT41: 10-Aug | BU41: 11-Aug | BV41: 12-Aug | BW41: 13-Aug | BX41: 14-Aug | BY41: 15-Aug | BZ41: 16-Aug | CA41: 17-Aug | CB41: 18-Aug | CC41: 19-Aug | CD41: 20-Aug | CE41: 21-Aug | CF41: 22-Aug | CG41: 23-Aug | CH41: 24-Aug | CI41: 25-Aug | CJ41: 26-Aug | CK41: 27-Aug | CL41: 28-Aug | CM41: 29-Aug | CN41: 30-Aug | CO41: 31-Aug
A42: SKU 1 - a | CG42: 1 | CI42: 1 | CJ42: 2 | CK42: 6 | CL42: 6 | CM42: 3 | CN42: 15 | CO42: 6
A43: SKU 1 - b | B43: 103 | C43: 78 | D43: 100 | E43: 93 | F43: 104 | G43: 111 | H43: 117 | I43: 105 | J43: 105 | K43: 102 | L43: 93 | M43: 93 | N43: 64 | O43: 99 | P43: 120 | Q43: 78 | R43: 92 | S43: 108 | T43: 98 | U43: 96 | V43: 85 | W43: 86 | X43: 86 | Y43: 107 | Z43: 90 | AA43: 100 | AB43: 98 | AC43: 90 | AD43: 95 | AE43: 62 | AF43: 79 | AG43: 109 | AH43: 78 | AI43: 102 | AJ43: 108 | AK43: 102 | AL43: 104 | AM43: 107 | AN43: 69 | AO43: 101 | AP43: 71 | AQ43: 92 | AR43: 103 | AS43: 102 | AT43: 123 | AU43: 88 | AV43: 99 | AW43: 90 | AX43: 89 | AY43: 105 | AZ43: 104 | BA43: 72 | BB43: 111 | BC43: 101 | BD43: 85 | BE43: 86 | BF43: 102 | BG43: 92 | BH43: 79 | BI43: 78 | BJ43: 100 | BK43: 106 | BL43: 98 | BM43: 121 | BN43: 81 | BO43: 122 | BP43: 110 | BQ43: 105 | BR43: 88 | BS43: 87 | BT43: 91 | BU43: 83 | BV43: 93 | BW43: 86 | BX43: 82 | BY43: 59 | BZ43: 65 | CA43: 88 | CB43: 78 | CC43: 106 | CD43: 77 | CE43: 98 | CF43: 90 | CG43: 79 | CH43: 93 | CI43: 89 | CJ43: 103 | CK43: 82 | CL43: 114 | CM43: 97 | CN43: 98 | CO43: 109
...

Sheet Supporting Analysis
A1: Blended Sales Trend | E1: Monthly Sales | I1: Platform Total | M1: Platform vs Date | W1: Top SKU | AA1: Growth % – EACH CHANNEL (WoW)
A3: Row Labels | B3: Sum of Sales | E3: Row Labels | F3: Sum of Sales | I3: Row Labels | J3: Sum of Sales | M3: Sum of Sales | N3: Column Labels | W3: Row Labels | X3: Sum of Sales | AA3: Sum of Sales2 | AB3: Column Labels
A4: 45444 | B4: 6219 | E4: Jun | F4: 157290 | I4: AMAZON NOW F | J4: 64160 | M4: Row Labels | N4: AMAZON NOW F | O4: Platform A | P4: Platform B | Q4: Platform C | R4: Platform D | S4: Platform E | T4: Grand Total | W4: SKU - 3 B | X4: 30662 | AA4: Row Labels | AB4: 22 | AC4: 23 | AD4: 24 | AE4: 25 | AF4: 26 | AG4: 27 | AH4: 28 | AI4: 29 | AJ4: 30 | AK4: 31 | AL4: 32 | AM4: 33 | AN4: 34 | AO4: 35 | AQ4: Platform | AR4: WoW Growth %
A5: 45445 | B5: 5586 | E5: Jul | F5: 245778 | I5: Platform A | J5: 214244 | M5: 45444 | O5: 2491 | P5: 399 | Q5: 888 | S5: 2441 | T5: 6219 | W5: SKU 1 - a | X5: 41398 | AA5: AMAZON NOW F | AC5: #NULL! | AD5: #NULL! | AF5: #NULL! | AG5: #NULL! | AI5: #NULL! | AK5: -0.79726416 | AL5: #NULL! | AM5: #NULL! | AO5: 2.2062277 | AQ5: =AA6 -> Platform A | AR5: =GETPIVOTDATA("[Measures].[Sum of Sales 3]",$AA$3,"[Append32141].[Platform]","[Append32141].[Platform].&[Platform A]","[Append32141].[Weeknum]","[Append32141].[Weeknum].&[35]") -> 0.0044185796
A6: 45446 | B6: 5903 | E6: Aug | F6: 160840 | I6: Platform B | J6: 52282 | M6: 45445 | O6: 2121 | P6: 327 | Q6: 659 | S6: 2479 | T6: 5586 | W6: SKU 1 - b | X6: 72016 | AA6: Platform A | AC6: 5.3026897 | AD6: 0.025541401 | AE6: -0.083783616 | AF6: -0.019929501 | AG6: 0.029464656 | AH6: -0.0032249395 | AI6: 0.074278781 | AJ6: -0.013991718 | AK6: 0.07553293 | AL6: 0.051295705 | AM6: -0.015138725 | AN6: 0.060457143 | AO6: 0.0044185796 | AQ6: =AA7 -> Platform B | AR6: =GETPIVOTDATA("[Measures].[Sum of Sales 3]",$AA$3,"[Append32141].[Platform]","[Append32141].[Platform].&[Platform B]","[Append32141].[Weeknum]","[Append32141].[Weeknum].&[35]") -> 0.049180328
A7: 45447 | B7: 5902 | E7: Grand Total | F7: 563908 | I7: Platform C | J7: 79798 | M7: 45446 | O7: 2237 | P7: 343 | Q7: 760 | S7: 2563 | T7: 5903 | W7: SKU 1 - c | X7: 121320 | AA7: Platform B | AC7: 5.2907268 | AD7: 0.049003984 | AE7: 0.0049373338 | AF7: -0.066137566 | AG7: 0.72885471 | AH7: -0.10463483 | AI7: 0.14143791 | AJ7: 0.15689418 | AK7: -0.085527618 | AL7: -0.027278632 | AM7: 0.13999555 | AN7: -0.059156579 | AO7: 0.049180328 | AQ7: =AA8 -> Platform C | AR7: =GETPIVOTDATA("[Measures].[Sum of Sales 3]",$AA$3,"[Append32141].[Platform]","[Append32141].[Platform].&[Platform C]","[Append32141].[Weeknum]","[Append32141].[Weeknum].&[35]") -> -0.050347747
A8: 45448 | B8: 5912 | I8: Platform D | J8: 58072 | M8: 45447 | O8: 2142 | P8: 377 | Q8: 720 | S8: 2663 | T8: 5902 | W8: SKU 1 - f | X8: 54300 | AA8: Platform C | AC8: 5.4662162 | AD8: 0.13549286 | AE8: -0.10506135 | AF8: -0.13247644 | AG8: 0.18767286 | AH8: 0.051397206 | AI8: -0.048093656 | AJ8: 0.08542463 | AK8: -0.021283111 | AL8: -0.062891114 | AM8: -0.066277129 | AN8: 0.18254962 | AO8: -0.050347747 | AQ8: =AA9 -> Platform D | AR8: =GETPIVOTDATA("[Measures].[Sum of Sales 3]",$AA$3,"[Append32141].[Platform]","[Append32141].[Platform].&[Platform D]","[Append32141].[Weeknum]","[Append32141].[Weeknum].&[35]") -> 2.2062277
A9: 45449 | B9: 6213 | I9: Platform E | J9: 95352 | M9: 45448 | O9: 2102 | P9: 408 | Q9: 802 | S9: 2600 | T9: 5912 | W9: SKU 1 - h | X9: 48004 | AA9: Platform D | AC9: #NULL! | AD9: #NULL! | AE9: #NULL! | AF9: #NULL! | AG9: #NULL! | AI9: 6.4671022 | AJ9: -0.0063742032 | AK9: -0.0071069182 | AL9: #NULL! | AM9: #NULL! | AO9: 2.2062277 | AQ9: =AA10 -> Platform E | AR9: =GETPIVOTDATA("[Measures].[Sum of Sales 3]",$AA$3,"[Append32141].[Platform]","[Append32141].[Platform].&[Platform E]","[Append32141].[Weeknum]","[Append32141].[Weeknum].&[35]") -> -0.72208437
A10: 45450 | B10: 6806 | I10: Grand Total | J10: 563908 | M10: 45449 | O10: 2271 | P10: 335 | Q10: 855 | S10: 2752 | T10: 6213 | W10: SKU 2 - a | X10: 29085 | AA10: Platform E | AC10: 5.6362147 | AD10: #NULL! | AF10: 1.7886179 | AG10: -0.17594752 | AH10: 0.41190518 | AI10: -0.010085823 | AJ10: -0.57214277 | AK10: #NULL! | AL10: #NULL! | AM10: #NULL! | AO10: -0.72208437 | AQ10: =AA5 -> AMAZON NOW F | AR10: =GETPIVOTDATA("[Measures].[Sum of Sales 3]",$AA$3,"[Append32141].[Platform]","[Append32141].[Platform].&[AMAZON NOW F]","[Append32141].[Weeknum]","[Append32141].[Weeknum].&[35]") -> 2.2062277
A11: 45451 | B11: 3829 | M11: 45450 | O11: 2333 | P11: 372 | Q11: 959 | S11: 3142 | T11: 6806 | W11: SKU 2 - B | X11: 56514
A12: 45452 | B12: 3200 | E12: Weekly Sales | M12: 45451 | O12: 2494 | P12: 348 | Q12: 987 | T12: 3829 | W12: SKU 2 - C | X12: 24843
A13: 45453 | B13: 3249 | M13: 45452 | O13: 2047 | P13: 333 | Q13: 820 | T13: 3200 | W13: SKU 2 - D | X13: 54684
A14: 45454 | B14: 3558 | E14: Row Labels | F14: Sum of Sales | I14: KPI | J14: Value | M14: 45453 | O14: 2112 | P14: 282 | Q14: 855 | T14: 3249 | W14: Grand Total | X14: 532826
A15: 45455 | B15: 3635 | E15: 22 | F15: 6219 | I15: Blended Sales – DoD | J15: =GETPIVOTDATA("[Measures].[Sum of Sales]",$A$3,"[Append321].[Date]","[Append321].[Date].&[2024-08-31T00:00:00]") -> 6575 | M15: 45454 | O15: 2274 | P15: 344 | Q15: 940 | T15: 3558
A16: 45456 | B16: 3531 | E16: 23 | F16: 40151 | I16: Blended Sales – WoW | J16: =GETPIVOTDATA("[Measures].[Sum of Sales 2]",$E$14,"[Append3214].[Weeknum]","[Append3214].[Weeknum].&[35]") -> 44331 | M16: 45455 | O16: 2393 | P16: 355 | Q16: 887 | T16: 3635
A17: 45457 | B17: 4062 | E17: 24 | F17: 25254 | I17: Blended Sales – MoM | J17: =GETPIVOTDATA("[Measures].[Sum of Sales]",$E$3,"[Append321].[Date (Month)]","[Append321].[Date (Month)].&[Aug]") -> 160840 | M17: 45456 | O17: 2243 | P17: 369 | Q17: 919 | T17: 3531 | AA17: Growth % – EACH CHANNEL (MoM)
A18: 45458 | B18: 4019 | E18: 25 | F18: 46793 | I18: Growth % blended DoD | J18: =(GETPIVOTDATA("[Measures].[Sum of Sales]",$A$3,"[Append321].[Date]","[Append321].[Date].&[2024-08-31T00:00:00]")-GETPIVOTDATA("[Measures].[Sum of Sales]",$A$3,"[Append321].[Date]","[Append321].[Date].&[2024-08-30T00:00:00]"))/GETPIVOTDATA("[Measures].[Sum of Sales]",$A$3,"[Append321].[Date]","[Append321].[Date].&[2024-08-30T00:00:00]") -> 0.053179561 | M18: 45457 | O18: 2504 | P18: 489 | Q18: 1069 | T18: 4062
A19: 45459 | B19: 5805 | E19: 26 | F19: 35711 | I19: Growth % blended WoW | J19: =(GETPIVOTDATA("[Measures].[Sum of Sales 2]",$E$14,"[Append3214].[Weeknum]","[Append3214].[Weeknum].&[35]")-GETPIVOTDATA("[Measures].[Sum of Sales 2]",$E$14,"[Append3214].[Weeknum]","[Append3214].[Weeknum].&[34]"))/GETPIVOTDATA("[Measures].[Sum of Sales 2]",$E$14,"[Append3214].[Weeknum]","[Append3214].[Weeknum].&[34]") -> 0.098471145 | M19: 45458 | O19: 2528 | P19: 461 | Q19: 1030 | T19: 4019 | AA19: Sum of Sales2 | AB19: Column Labels
A20: 45460 | B20: 5741 | E20: 27 | F20: 36474 | I20: Growth % blended MoM | J20: =(GETPIVOTDATA("[Measures].[Sum of Sales]",$E$3,"[Append321].[Date (Month)]","[Append321].[Date (Month)].&[Aug]")-GETPIVOTDATA("[Measures].[Sum of Sales]",$E$3,"[Append321].[Date (Month)]","[Append321].[Date (Month)].&[Jul]"))/GETPIVOTDATA("[Measures].[Sum of Sales]",$E$3,"[Append321].[Date (Month)]","[Append321].[Date (Month)].&[Jul]") -> -0.3455883 | M20: 45459 | N20: 2441 | O20: 2129 | P20: 421 | Q20: 814 | T20: 5805 | AA20: Row Labels | AB20: Jun | AC20: Jul | AD20: Aug | AJ20: Platform | AK20: MoM Growth %
A21: 45461 | B21: 5933 | E21: 28 | F21: 61728 | M21: 45460 | N21: 2479 | O21: 1975 | P21: 392 | Q21: 895 | T21: 5741 | AA21: AMAZON NOW F | AC21: 1 | AD21: -0.77896996 | AJ21: =AA22 -> Platform A | AK21: =GETPIVOTDATA("[Measures].[Sum of Sales 3]",$AA$19,"[Append32141].[Platform]","[Append32141].[Platform].&[Platform A]","[Append32141].[Date (Month)]","[Append32141].[Date (Month)].&[Aug]") -> 0.17650588
A22: 45462 | B22: 5900 | E22: 29 | F22: 58125 | M22: 45461 | N22: 2563 | O22: 2150 | P22: 420 | Q22: 800 | T22: 5933 | AA22: Platform A | AC22: 0.042934111 | AD22: 0.17650588 | AJ22: =AA23 -> Platform B | AK22: =GETPIVOTDATA("[Measures].[Sum of Sales 3]",$AA$19,"[Append32141].[Platform]","[Append32141].[Platform].&[Platform B]","[Append32141].[Date (Month)]","[Append32141].[Date (Month)].&[Aug]") -> 0.10679761
A23: 45463 | B23: 5680 | E23: 30 | F23: 65456 | M23: 45462 | N23: 2663 | O23: 2064 | P23: 351 | Q23: 822 | T23: 5900 | AA23: Platform B | AC23: 0.76262171 | AD23: 0.10679761 | AJ23: =AA24 -> Platform C | AK23: =GETPIVOTDATA("[Measures].[Sum of Sales 3]",$AA$19,"[Append32141].[Platform]","[Append32141].[Platform].&[Platform C]","[Append32141].[Date (Month)]","[Append32141].[Date (Month)].&[Aug]") -> -0.013892898
A24: 45464 | B24: 8562 | E24: 31 | F24: 46842 | M24: 45463 | N24: 2600 | O24: 1988 | P24: 316 | Q24: 776 | T24: 5680 | AA24: Platform C | AC24: 0.11926976 | AD24: -0.013892898 | AJ24: =AA25 -> Platform D | AK24: =GETPIVOTDATA("[Measures].[Sum of Sales 3]",$AA$19,"[Append32141].[Platform]","[Append32141].[Platform].&[Platform D]","[Append32141].[Date (Month)]","[Append32141].[Date (Month)].&[Aug]") -> -0.65171461
A25: 45465 | B25: 9172 | E25: 32 | F25: 28252 | M25: 45464 | N25: 2752 | O25: 2159 | P25: 363 | Q25: 847 | S25: 2441 | T25: 8562 | AA25: Platform D | AD25: -0.65171461 | AJ25: =AA26 -> Platform E | AK25: =GETPIVOTDATA("[Measures].[Sum of Sales 3]",$AA$19,"[Append32141].[Platform]","[Append32141].[Platform].&[Platform E]","[Append32141].[Date (Month)]","[Append32141].[Date (Month)].&[Aug]") -> -0.83464441
A26: 45466 | B26: 5456 | E26: 33 | F26: 28215 | M26: 45465 | N26: 3142 | O26: 2287 | P26: 383 | Q26: 881 | S26: 2479 | T26: 9172 | AA26: Platform E | AC26: 0.33669528 | AD26: -0.83464441 | AJ26: =AA21 -> AMAZON NOW F | AK26: =GETPIVOTDATA("[Measures].[Sum of Sales 3]",$AA$19,"[Append32141].[Platform]","[Append32141].[Platform].&[AMAZON NOW F]","[Append32141].[Date (Month)]","[Append32141].[Date (Month)].&[Aug]") -> -0.77896996
A27: 45467 | B27: 5727 | E27: 34 | F27: 40357 | M27: 45466 | O27: 1873 | P27: 310 | Q27: 710 | S27: 2563 | T27: 5456
A28: 45468 | B28: 5684 | E28: 35 | F28: 44331 | M28: 45467 | O28: 1994 | P28: 349 | Q28: 721 | S28: 2663 | T28: 5727
A29: 45469 | B29: 5846 | E29: Grand Total | F29: 563908 | M29: 45468 | O29: 2062 | P29: 317 | Q29: 705 | S29: 2600 | T29: 5684
A30: 45470 | B30: 6208 | M30: 45469 | O30: 2063 | P30: 347 | Q30: 684 | S30: 2752 | T30: 5846
A31: 45471 | B31: 3323 | M31: 45470 | O31: 2019 | P31: 330 | Q31: 717 | S31: 3142 | T31: 6208
A32: 45472 | B32: 3467 | M32: 45471 | O32: 2239 | P32: 375 | Q32: 709 | T32: 3323
A33: 45473 | B33: 3162 | M33: 45472 | O33: 2208 | P33: 443 | Q33: 816 | T33: 3467
A34: 45474 | B34: 3428 | M34: 45473 | O34: 2017 | P34: 433 | Q34: 712 | T34: 3162
A35: 45475 | B35: 5935 | M35: 45474 | O35: 2084 | P35: 527 | Q35: 817 | T35: 3428
A36: 45476 | B36: 5789 | M36: 45475 | O36: 2188 | P36: 727 | Q36: 877 | S36: 2143 | T36: 5935
A37: 45477 | B37: 5814 | M37: 45476 | O37: 2175 | P37: 607 | Q37: 767 | S37: 2240 | T37: 5789
A38: 45478 | B38: 6123 | M38: 45477 | O38: 2024 | P38: 642 | Q38: 826 | S38: 2322 | T38: 5814
A39: 45479 | B39: 6223 | M39: 45478 | O39: 2143 | P39: 565 | Q39: 917 | S39: 2498 | T39: 6123
A40: 45480 | B40: 7951 | M40: 45479 | O40: 2253 | P40: 771 | Q40: 1096 | S40: 2103 | T40: 6223
A41: 45481 | B41: 7919 | M41: 45480 | N41: 2441 | O41: 1876 | P41: 521 | Q41: 916 | S41: 2197 | T41: 7951
...
